<?xml version="1.0" encoding="utf-8"?>
<!-- This URDF was automatically created by SolidWorks to URDF Exporter! Originally created by
Stephen Brawner (brawner@gmail.com) 
     Commit Version: 1.6.0-4-g7f85cfe  Build Version: 1.6.7995.38578
     For more information, please see http://wiki.ros.org/sw_urdf_exporter -->
<robot name="h1_description">
  <mujoco>
    <compiler meshdir="../meshes" discardvisual="false" />
  </mujoco>


  <!-- [CAUTION] uncomment when convert to mujoco -->
  <!-- <link name="world"></link>
  <joint name="floating_base_joint" type="floating">
    <parent link="world" />
    <child link="pelvis" />
  </joint> -->


  <link name="pelvis">
    <inertial>
      <origin xyz="-0.0002 4E-05 -0.04522" rpy="0 0 0" />
      <mass value="5.39" />
      <inertia ixx="0.044582" ixy="8.7034E-05" ixz="-1.9893E-05" iyy="0.0082464" iyz="4.021E-06" izz="0.049021" />
    </inertial>
    <visual>
      <origin xyz="0 0 0" rpy="0 0 0" />
      <geometry>
        <mesh filename="package://h1_description/meshes/pelvis.dae" />
      </geometry>
      <material name="">
        <color rgba="0.1 0.1 0.1 1" />
      </material>
    </visual>
    <collision>
      <origin xyz="0 0 0" rpy="0 0 0" />
      <geometry>
        <sphere radius="0.05"/>
      </geometry>
    </collision>
  </link>
  <link name="left_hip_yaw_link">
    <inertial>
      <origin xyz="-0.04923 0.0001 0.0072" rpy="0 0 0" />
      <mass value="2.244" />
      <inertia ixx="0.0025731" ixy="9.159E-06" ixz="-0.00051948" iyy="0.0030444" iyz="1.949E-06" izz="0.0022883" />
    </inertial>
    <visual>
      <origin xyz="0 0 0" rpy="0 0 0" />
      <geometry>
        <mesh filename="package://h1_description/meshes/left_hip_yaw_link.dae" />
      </geometry>
      <material name="">
        <color rgba="0.1 0.1 0.1 1" />
      </material>
    </visual>
    <collision>
      <origin xyz="0.02 0 0" rpy="0 1.5707963267948966192313216916398 0" />
      <geometry>
        <cylinder radius="0.01" length="0.02"/>
      </geometry>
    </collision>
  </link>
  <joint name="left_hip_yaw_joint" type="revolute">
    <origin xyz="0 0.0875 -0.1742" rpy="0 0 0" />
    <parent link="pelvis" />
    <child link="left_hip_yaw_link" />
    <axis xyz="0 0 1" />
    <limit lower="-0.43" upper="0.43" effort="200" velocity="23" />
  </joint>
  <link name="left_hip_roll_link">
    <inertial>
      <origin xyz="-0.0058 -0.00319 -9E-05" rpy="0 0 0" />
      <mass value="2.232" />
      <inertia ixx="0.0020603" ixy="3.2115E-05" ixz="2.878E-06" iyy="0.0022482" iyz="-7.813E-06" izz="0.0024323" />
    </inertial>
    <visual>
      <origin xyz="0 0 0" rpy="0 0 0" />
      <geometry>
        <mesh filename="package://h1_description/meshes/left_hip_roll_link.dae" />
      </geometry>
      <material name="">
        <color rgba="0.1 0.1 0.1 1" />
      </material>
    </visual>
    <collision>
      <origin xyz="0 0.06 0" rpy="1.5707963267948966192313216916398 0 0" />
      <geometry>
        <cylinder radius="0.02" length="0.01"/>
      </geometry>
    </collision>
  </link>
  <joint name="left_hip_roll_joint" type="revolute">
    <origin xyz="0.039468 0 0" rpy="0 0 0" />
    <parent link="left_hip_yaw_link" />
    <child link="left_hip_roll_link" />
    <axis xyz="1 0 0" />
    <limit lower="-0.43" upper="0.43" effort="200" velocity="23" />
  </joint>
  <link name="left_hip_pitch_link">
    <inertial>
      <origin xyz="0.00746 -0.02346 -0.08193" rpy="0 0 0" />
      <mass value="4.152" />
      <inertia ixx="0.082618" ixy="-0.00066654" ixz="0.0040725" iyy="0.081579" iyz="0.0072024" izz="0.0060081" />
    </inertial>
    <visual>
      <origin xyz="0 0 0" rpy="0 0 0" />
      <geometry>
        <mesh filename="package://h1_description/meshes/left_hip_pitch_link.dae" />
      </geometry>
      <material name="">
        <color rgba="0.1 0.1 0.1 1" />
      </material>
    </visual>
    <collision>
      <origin xyz="0 0 -0.2" rpy="0 0 0" />
      <geometry>
        <cylinder radius="0.05" length="0.2"/>
      </geometry>
    </collision>
  </link>
  <joint name="left_hip_pitch_joint" type="revolute">
    <origin xyz="0 0.11536 0" rpy="0 0 0" />
    <parent link="left_hip_roll_link" />
    <child link="left_hip_pitch_link" />
    <axis xyz="0 1 0" />
    <limit lower="-3.14" upper="2.53" effort="200" velocity="23" />
  </joint>
  <link name="left_knee_link">
    <inertial>
      <origin xyz="-0.00136 -0.00512 -0.1384" rpy="0 0 0" />
      <mass value="1.721" />
      <inertia ixx="0.012205" ixy="-6.8431E-05" ixz="0.0010862" iyy="0.012509" iyz="0.00022549" izz="0.0020629" />
    </inertial>
    <visual>
      <origin xyz="0 0 0" rpy="0 0 0" />
      <geometry>
        <mesh filename="package://h1_description/meshes/left_knee_link.dae" />
      </geometry>
      <material name="">
        <color rgba="0.1 0.1 0.1 1" />
      </material>
    </visual>
    <collision>
      <origin xyz="0 0 -0.2" rpy="0 0 0" />
      <geometry>
        <cylinder radius="0.05" length="0.2"/>
      </geometry>
    </collision>
  </link>
  <joint name="left_knee_joint" type="revolute">
    <origin xyz="0 0 -0.4" rpy="0 0 0" />
    <parent link="left_hip_pitch_link" />
    <child link="left_knee_link" />
    <axis xyz="0 1 0" />
    <limit lower="-0.26" upper="2.05" effort="300" velocity="14" />
  </joint>
  <link name="left_ankle_link">
    <inertial>
      <origin xyz="0.042575 -0.000001 -0.044672" rpy="0 0 0" />
      <mass value="0.474" />
      <inertia ixx="0.000159668" ixy="-0.000000005" ixz="0.000141063" iyy="0.002900286" iyz="0.000000014" izz="0.002805438" />
    </inertial>
    <visual>
      <origin xyz="0 0 0" rpy="0 0 0" />
      <geometry>
        <mesh filename="package://h1_description/meshes/left_ankle_link.dae" />
      </geometry>
      <material name="">
        <color rgba="0.1 0.1 0.1 1" />
      </material>
    </visual>
    <collision>
      <origin xyz="0.05 0.0 -0.05" rpy="0 0 0" />
      <geometry>
        <box size="0.28 0.03 0.024"/>
      </geometry>
    </collision>
  </link>
  <joint name="left_ankle_joint" type="revolute">
    <origin xyz="0 0 -0.4" rpy="0 0 0" />
    <parent link="left_knee_link" />
    <child link="left_ankle_link" />
    <axis xyz="0 1 0" />
    <limit lower="-0.87" upper="0.52" effort="40" velocity="9" />
  </joint>
  <link name="left_foot_front"></link>
  <joint name="left_foot_front_joint" type="fixed">
    <origin xyz="0.2 0 -0.07" rpy="0 0 0" />
    <parent link="left_ankle_link" />
    <child link="left_foot_front" />
  </joint>
  <link name="left_foot_back"></link>
  <joint name="left_foot_back_joint" type="fixed">
    <origin xyz="-0.1 0 -0.07" rpy="0 0 0" />
    <parent link="left_ankle_link" />
    <child link="left_foot_back" />
  </joint>
  <link name="left_foot_center"></link>
  <joint name="left_foot_center_joint" type="fixed">
    <origin xyz="0 0 -0.07" rpy="0 0 0" />
    <parent link="left_ankle_link" />
    <child link="left_foot_center" />
  </joint>
</robot>