<?xml version="1.0" encoding="utf-8"?>
<!-- This URDF was automatically created by SolidWorks to URDF Exporter! Originally created by
Stephen Brawner (brawner@gmail.com) 
     Commit Version: 1.6.0-4-g7f85cfe  Build Version: 1.6.7995.38578
     For more information, please see http://wiki.ros.org/sw_urdf_exporter -->
<robot name="h1_description">
  <mujoco>
    <compiler meshdir="../meshes" discardvisual="false" />
  </mujoco>


  <!-- [CAUTION] uncomment when convert to mujoco -->
  <link name="world"></link>
  <joint name="floating_base_joint" type="floating">
    <parent link="world" />
    <child link="pelvis" />
  </joint>


  <link name="pelvis">
    <inertial>
      <origin xyz="-0.0002 4E-05 -0.04522" rpy="0 0 0" />
      <mass value="5.39" />
      <inertia ixx="0.044582" ixy="8.7034E-05" ixz="-1.9893E-05" iyy="0.0082464" iyz="4.021E-06" izz="0.049021" />
    </inertial>
    <visual>
      <origin xyz="0 0 0" rpy="0 0 0" />
      <geometry>
        <mesh filename="package://h1_description/meshes/pelvis.dae" />
      </geometry>
      <material name="">
        <color rgba="0.1 0.1 0.1 1" />
      </material>
    </visual>
    <collision>
      <origin xyz="0 0 0" rpy="0 0 0" />
      <geometry>
        <sphere radius="0.05"/>
      </geometry>
    </collision>
  </link>
  <link name="torso_link">
    <inertial>
      <origin xyz="0.000489 0.002797 0.20484" rpy="0 0 0" />
      <mass value="17.789" />
      <inertia ixx="0.4873" ixy="-0.00053763" ixz="0.0020276" iyy="0.40963" iyz="-0.00074582" izz="0.12785" />
    </inertial>
    <visual>
      <origin xyz="0 0 0" rpy="0 0 0" />
      <geometry>
        <mesh filename="package://h1_description/meshes/torso_link.dae" />
      </geometry>
      <material name="">
        <color rgba="0.1 0.1 0.1 1" />
      </material>
    </visual>
    <collision>
      <origin xyz="0 0 0.15" rpy="0 0 0" />
      <geometry>
        <box size="0.08 0.16 0.1"/>
      </geometry>
    </collision>
  </link>
  <joint name="torso_joint" type="fixed">
    <origin xyz="0 0 0" rpy="0 0 0" />
    <parent link="pelvis" />
    <child link="torso_link" />
    <axis xyz="0 0 1" />
  </joint>
  <link name="right_shoulder_pitch_link">
    <inertial>
      <origin xyz="0.005045 -0.053657 -0.015715" rpy="0 0 0" />
      <mass value="1.033" />
      <inertia ixx="0.0012985" ixy="1.7333E-05" ixz="8.683E-06" iyy="0.00087279" iyz="-3.9656E-05" izz="0.00097338" />
    </inertial>
    <visual>
      <origin xyz="0 0 0" rpy="0 0 0" />
      <geometry>
        <mesh filename="package://h1_description/meshes/right_shoulder_pitch_link.dae" />
      </geometry>
      <material name="">
        <color rgba="0.1 0.1 0.1 1" />
      </material>
    </visual>
    <collision>
      <origin xyz="0 0.05  0" rpy="-1.5707963267948966192313216916398 0 0" />
      <geometry>
        <cylinder radius="0.03" length="0.04"/>
      </geometry>
    </collision>
  </link>
  <joint name="right_shoulder_pitch_joint" type="revolute">
    <origin xyz="0.0055 -0.15535 0.42999" rpy="-0.43633 0 0" />
    <parent link="torso_link" />
    <child link="right_shoulder_pitch_link" />
    <axis xyz="0 1 0" />
    <limit lower="-2.87" upper="2.87" effort="40" velocity="9" />
  </joint>
  <link name="right_shoulder_roll_link">
    <inertial>
      <origin xyz="0.000679 -0.00115 -0.094076" rpy="0 0 0" />
      <mass value="0.793" />
      <inertia ixx="0.0015742" ixy="-2.298E-06" ixz="-7.2265E-05" iyy="0.0016973" iyz="6.3691E-05" izz="0.0010183" />
    </inertial>
    <visual>
      <origin xyz="0 0 0" rpy="0 0 0" />
      <geometry>
        <mesh filename="package://h1_description/meshes/right_shoulder_roll_link.dae" />
      </geometry>
      <material name="">
        <color rgba="0.1 0.1 0.1 1" />
      </material>
    </visual>
    <collision>
      <origin xyz="0 0 -0.04" rpy="0 0 0" />
      <geometry>
        <cylinder radius="0.04" length="0.01"/>
      </geometry>
    </collision>
  </link>
  <joint name="right_shoulder_roll_joint" type="revolute">
    <origin xyz="-0.0055 -0.0565 -0.0165" rpy="0.43633 0 0" />
    <parent link="right_shoulder_pitch_link" />
    <child link="right_shoulder_roll_link" />
    <axis xyz="1 0 0" />
    <limit lower="-3.11" upper="0.34" effort="40" velocity="9" />
  </joint>
  <link name="right_shoulder_yaw_link">
    <inertial>
      <origin xyz="0.01365 -0.002767 -0.16266" rpy="0 0 0" />
      <mass value="0.839" />
      <inertia ixx="0.003664" ixy="1.0671E-05" ixz="0.00034733" iyy="0.0040789" iyz="-7.0213E-05" izz="0.00066383" />
    </inertial>
    <visual>
      <origin xyz="0 0 0" rpy="0 0 0" />
      <geometry>
        <mesh filename="package://h1_description/meshes/right_shoulder_yaw_link.dae" />
      </geometry>
      <material name="">
        <color rgba="0.1 0.1 0.1 1" />
      </material>
    </visual>
    <collision>
      <origin xyz="0 0 -0.11" rpy="0 0 0" />
      <geometry>
        <cylinder radius="0.04" length="0.01"/>
      </geometry>
    </collision>
  </link>
  <joint name="right_shoulder_yaw_joint" type="revolute">
    <origin xyz="0 0 -0.1343" rpy="0 0 0" />
    <parent link="right_shoulder_roll_link" />
    <child link="right_shoulder_yaw_link" />
    <axis xyz="0 0 1" />
    <limit lower="-4.45" upper="1.3" effort="18" velocity="20" />
  </joint>
  <link name="right_elbow_link">
    <inertial>
      <origin xyz="0.164862 -0.000118 -0.015734" rpy="0 0 0" />
      <mass value="0.723" />
      <inertia ixx="0.00042388" ixy="3.6086E-05" ixz="0.00029293" iyy="0.0060062" iyz="-4.664E-06" izz="0.0060023" />
    </inertial>
    <visual>
      <origin xyz="0 0 0" rpy="0 0 0" />
      <geometry>
        <mesh filename="package://h1_description/meshes/right_elbow_link.dae" />
      </geometry>
      <material name="">
        <color rgba="0.1 0.1 0.1 1" />
      </material>
    </visual>
    <collision>
      <origin xyz="0.125 0 0" rpy="0 1.57 0" />
      <geometry>
        <cylinder radius="0.03" length="0.09"/>
      </geometry>
    </collision>
  </link>
  <joint name="right_elbow_joint" type="revolute">
    <origin xyz="0.0185 0 -0.198" rpy="0 0 0" />
    <parent link="right_shoulder_yaw_link" />
    <child link="right_elbow_link" />
    <axis xyz="0 1 0" />
    <limit lower="-1.25" upper="2.61" effort="18" velocity="20" />
  </joint>
  <link name="right_hand_center"></link>
  <joint name="right_hand_center_joint" type="fixed">
    <origin xyz="0.2605 0 -0.0185" rpy="0 0 0" />
    <parent link="right_elbow_link" />
    <child link="right_hand_center" />
  </joint>
</robot>